<?xml version="1.0" ?>
<robot name="2wheel" xmlns:xacro="http://www.ros.org/wiki/xacro">

  <material name="black">
    <color rgba="0.0 0.0 0.0 1.0"/>
  </material>
  <material name="blue">
    <color rgba="0.203125 0.23828125 0.28515625 1.0"/>
  </material>
  <material name="green">
    <color rgba="0.0 0.8 0.0 1.0"/>
  </material>
  <material name="grey">
    <color rgba="0.2 0.2 0.2 1.0"/>
  </material>
  <material name="orange">
    <color rgba="1.0 0.423529411765 0.0392156862745 1.0"/>
  </material>
  <material name="brown">
    <color rgba="0.870588235294 0.811764705882 0.764705882353 1.0"/>
  </material>
  <material name="red">
    <color rgba="0.80078125 0.12890625 0.1328125 1.0"/>
  </material>
  <material name="white">
    <color rgba="1.0 1.0 1.0 1.0"/>
  </material>
  

<!-- Start: For URDF to Gazebo compatibility -->

  <gazebo reference="link_chassis">
    <material>Gazebo/Black</material>
  </gazebo>
  <gazebo reference="link_left_wheel">
    <material>Gazebo/Red</material>
  </gazebo>
  <gazebo reference="link_right_wheel">
    <material>Gazebo/Red</material>
  </gazebo>
  
  <gazebo>
    <plugin filename="libgazebo_ros_diff_drive.so" name="differential_drive_controller">
      <legacyMode>false</legacyMode>
      <alwaysOn>true</alwaysOn>
      <updateRate>10</updateRate>
      <leftJoint>joint_left_wheel</leftJoint>
      <rightJoint>joint_right_wheel</rightJoint>
      <wheelSeparation>0.34</wheelSeparation>
      <wheelDiameter>0.2</wheelDiameter>
      <torque>10</torque>
      <commandTopic>cmd_vel</commandTopic>
      <odometryTopic>odom</odometryTopic>
      <odometryFrame>odom</odometryFrame>
      <robotBaseFrame>link_chassis</robotBaseFrame>
    </plugin>
  </gazebo>
  <gazebo>
      <plugin name="imu_plugin" filename="libgazebo_ros_imu.so">
          <alwaysOn>true</alwaysOn>
					<updateRate>50</updateRate>
          <bodyName>imu_link</bodyName>
          <topicName>imu</topicName>
          <serviceName>imu_service</serviceName>
          <gaussianNoise>0.0</gaussianNoise>
          <rpyOffsets>0 0 0</rpyOffsets>
          <accelDrift>0.5 0.5 0.5</accelDrift>
          <accelGaussianNoise>0.35 0.35 0.3</accelGaussianNoise>
          <rateDrift>0.0 0.0 0.0</rateDrift>
          <rateGaussianNoise>0.00 0.00 0.00</rateGaussianNoise>
          <headingDrift>0.0</headingDrift>
          <headingGaussianNoise>0.00</headingGaussianNoise>
          <updateRate>00</updateRate>
      </plugin>
   </gazebo>
  
<!-- End: For URDF to Gazebo compatibility -->

	<link name="dummy_link"/>
	<link name="imu_link"/>

  <link name="link_chassis">
    <!-- pose and inertial -->
    <pose>0 0 0.1 0 0 0</pose>
    <inertial>
      <mass value="2"/>
      <origin rpy="0 0 0" xyz="0 0 0.3"/>
      <inertia ixx="0.075" ixy="0" ixz="0" iyy="0.061667" iyz="0" izz="0.01667"/>
    </inertial>
    <!-- body -->
    <collision name="collision_chassis">
      <origin rpy="0 0 0" xyz="0 0 0.3"/>
      <geometry>
        <box size="0.1 0.3 0.6"/>
      </geometry>
    </collision>
    <visual>
      <origin rpy="0 0 0" xyz="0 0 0.3"/>
      <geometry>
        <box size="0.1 0.3 0.6"/>
      </geometry>
      <material name="black"/>
    </visual>
  </link>
  
	<joint name="Base" type="fixed">
    <origin rpy="0 0 0" xyz="0 0 0"/>
		<child link="link_chassis"/>
    <parent link="dummy_link"/>
  </joint>
	<joint name="Imu" type="fixed">
    <origin rpy="0 0 0" xyz="0 0 0.3"/>
		<child link="imu_link"/>
    <parent link="link_chassis"/>
  </joint>

  <link name="link_left_wheel">
    <inertial>
      <mass value="0.2"/>
      <origin rpy="0 1.5707 1.5707" xyz="0 0 0"/>
      <inertia ixx="0.001" ixy="0" ixz="0" iyy="0.0005" iyz="0" izz="0.0005"/>
    </inertial>
    <collision name="link_left_wheel_collision">
      <origin rpy="0 1.5707 1.5707" xyz="0 0 0"/>
      <geometry>
        <cylinder length="0.04" radius="0.1"/>
      </geometry>
    </collision>
    <visual name="link_left_wheel_visual">
      <origin rpy="0 1.5707 1.5707" xyz="0 0 0"/>
      <geometry>
        <cylinder length="0.04" radius="0.1"/>
      </geometry>
    </visual>
  </link>
  
  <joint name="joint_left_wheel" type="continuous">
    <origin rpy="0 0 0" xyz="0 0.17 0"/>
    <child link="link_left_wheel"/>
    <parent link="link_chassis"/>
    <axis rpy="0 0 0" xyz="0 1 0"/>
    <limit effort="10000" velocity="1000"/>
    <joint_properties damping="1.0" friction="1.0"/>
  </joint>
  
  <link name="link_right_wheel">
    <inertial>
      <mass value="0.2"/>
      <origin rpy="0 1.5707 1.5707" xyz="0 0 0"/>
      <inertia ixx="0.001" ixy="0" ixz="0" iyy="0.0005" iyz="0" izz="0.0005"/>
    </inertial>
    <collision name="link_right_wheel_collision">
      <origin rpy="0 1.5707 1.5707" xyz="0 0 0"/>
      <geometry>
        <cylinder length="0.04" radius="0.1"/>
      </geometry>
    </collision>
    <visual name="link_right_wheel_visual">
      <origin rpy="0 1.5707 1.5707" xyz="0 0 0"/>
      <geometry>
        <cylinder length="0.04" radius="0.1"/>
      </geometry>
    </visual>
  </link>
  
  <joint name="joint_right_wheel" type="continuous">
    <origin rpy="0 0 0" xyz="0 -0.17 0"/>
    <child link="link_right_wheel"/>
    <parent link="link_chassis"/>
    <axis rpy="0 0 0" xyz="0 1 0"/>
    <limit effort="10000" velocity="1000"/>
    <joint_properties damping="1.0" friction="1.0"/>
  </joint>
</robot>
